Server exception occurred
Traceback (most recent call last):
  File "http.py", line 138, in client_thread
    requestData= recv_timeout(clientSocket)
  File "http.py", line 65, in recv_timeout
    part = socket.recv(BUFF_SIZE)
OSError: [Errno 9] Bad file descriptor
Server exception occurred
Traceback (most recent call last):
  File "http.py", line 138, in client_thread
    requestData= recv_timeout(clientSocket)
  File "http.py", line 65, in recv_timeout
    part = socket.recv(BUFF_SIZE)
OSError: [Errno 9] Bad file descriptor
Server exception occurred
Traceback (most recent call last):
  File "http.py", line 170, in client_thread
    requestedFile = open(url, "rb")
FileNotFoundError: [Errno 2] No such file or directory: './a/img_chania.jpg'
Server exception occurred
Traceback (most recent call last):
  File "http.py", line 170, in client_thread
    requestedFile = open(url, "rb")
FileNotFoundError: [Errno 2] No such file or directory: './a/1920px-HTTP_logo.svg.png'
Server exception occurred
Traceback (most recent call last):
  File "http.py", line 170, in client_thread
    requestedFile = open(url, "rb")
FileNotFoundError: [Errno 2] No such file or directory: './a/traceroute.png'
Server exception occurred
Traceback (most recent call last):
  File "http.py", line 138, in client_thread
    requestData= recv_timeout(clientSocket)
  File "http.py", line 65, in recv_timeout
    part = socket.recv(BUFF_SIZE)
OSError: [Errno 9] Bad file descriptor
Server exception occurred
Traceback (most recent call last):
  File "http.py", line 138, in client_thread
    requestData= recv_timeout(clientSocket)
  File "http.py", line 65, in recv_timeout
    part = socket.recv(BUFF_SIZE)
OSError: [Errno 9] Bad file descriptor
Server exception occurred
Traceback (most recent call last):
  File "http.py", line 138, in client_thread
    requestData= recv_timeout(clientSocket)
  File "http.py", line 65, in recv_timeout
    part = socket.recv(BUFF_SIZE)
OSError: [Errno 9] Bad file descriptor
Server exception occurred
Traceback (most recent call last):
  File "http.py", line 139, in client_thread
    requestData= recv_timeout(clientSocket)
  File "http.py", line 65, in recv_timeout
    part = socket.recv(BUFF_SIZE)
OSError: [Errno 9] Bad file descriptor
Server exception occurred
Traceback (most recent call last):
  File "http.py", line 141, in client_thread
    requestData= recv_timeout(clientSocket)
  File "http.py", line 69, in recv_timeout
    data+=part
UnboundLocalError: local variable 'part' referenced before assignment
Server exception occurred
Traceback (most recent call last):
  File "http.py", line 141, in client_thread
    requestData= recv_timeout(clientSocket)
  File "http.py", line 69, in recv_timeout
    data+=part
UnboundLocalError: local variable 'part' referenced before assignment
Server exception occurred
Traceback (most recent call last):
  File "http.py", line 141, in client_thread
    requestData= recv_timeout(clientSocket)
  File "http.py", line 69, in recv_timeout
    data+=part
UnboundLocalError: local variable 'part' referenced before assignment
Server exception occurred
Traceback (most recent call last):
  File "http.py", line 141, in client_thread
    requestData= recv_timeout(clientSocket)
  File "http.py", line 69, in recv_timeout
    data+=part
UnboundLocalError: local variable 'part' referenced before assignment
Server exception occurred
Traceback (most recent call last):
  File "http.py", line 141, in client_thread
    requestData= recv_timeout(clientSocket)
  File "http.py", line 69, in recv_timeout
    data+=part
UnboundLocalError: local variable 'part' referenced before assignment
Server exception occurred
Traceback (most recent call last):
  File "http.py", line 141, in client_thread
    requestData= recv_timeout(clientSocket)
  File "http.py", line 69, in recv_timeout
    data+=part
UnboundLocalError: local variable 'part' referenced before assignment
Server exception occurred
Traceback (most recent call last):
  File "http.py", line 141, in client_thread
    requestData= recv_timeout(clientSocket)
  File "http.py", line 69, in recv_timeout
    data+=part
UnboundLocalError: local variable 'part' referenced before assignment
Server exception occurred
Traceback (most recent call last):
  File "http.py", line 141, in client_thread
    requestData= recv_timeout(clientSocket)
  File "http.py", line 69, in recv_timeout
    data+=part
UnboundLocalError: local variable 'part' referenced before assignment
Server exception occurred
Traceback (most recent call last):
  File "http.py", line 146, in client_thread
    requestBody = parse_body(requestData)
  File "http.py", line 85, in parse_body
    _, body = data.split("\r\n\r\n")
ValueError: not enough values to unpack (expected 2, got 1)
Server exception occurred
Traceback (most recent call last):
  File "http.py", line 146, in client_thread
    requestBody = parse_body(requestData)
  File "http.py", line 85, in parse_body
    _, body = data.split("\r\n\r\n")
ValueError: not enough values to unpack (expected 2, got 1)
Server exception occurred
Traceback (most recent call last):
  File "http.py", line 146, in client_thread
    requestBody = parse_body(requestData)
  File "http.py", line 85, in parse_body
    _, body = data.split("\r\n\r\n")
ValueError: not enough values to unpack (expected 2, got 1)
Server exception occurred
Traceback (most recent call last):
  File "http.py", line 173, in client_thread
    requestedFile = open(url, "rb")
FileNotFoundError: [Errno 2] No such file or directory: './a/img_chania.jpg'
Server exception occurred
Traceback (most recent call last):
  File "http.py", line 173, in client_thread
    requestedFile = open(url, "rb")
FileNotFoundError: [Errno 2] No such file or directory: './a/1920px-HTTP_logo.svg.png'
Server exception occurred
Traceback (most recent call last):
  File "http.py", line 173, in client_thread
    requestedFile = open(url, "rb")
FileNotFoundError: [Errno 2] No such file or directory: './a/traceroute.png'
Server exception occurred
Traceback (most recent call last):
  File "http.py", line 146, in client_thread
    requestBody = parse_body(requestData)
  File "http.py", line 85, in parse_body
    _, body = data.split("\r\n\r\n")
ValueError: not enough values to unpack (expected 2, got 1)
Server exception occurred
Traceback (most recent call last):
  File "http.py", line 146, in client_thread
    requestBody = parse_body(requestData)
  File "http.py", line 85, in parse_body
    _, body = data.split("\r\n\r\n")
ValueError: not enough values to unpack (expected 2, got 1)
Server exception occurred
Traceback (most recent call last):
  File "http.py", line 146, in client_thread
    requestBody = parse_body(requestData)
  File "http.py", line 85, in parse_body
    _, body = data.split("\r\n\r\n")
ValueError: not enough values to unpack (expected 2, got 1)
Server exception occurred
Traceback (most recent call last):
  File "http.py", line 146, in client_thread
    requestBody = parse_body(requestData)
  File "http.py", line 85, in parse_body
    _, body = data.split("\r\n\r\n")
ValueError: not enough values to unpack (expected 2, got 1)
Server exception occurred
Traceback (most recent call last):
  File "http.py", line 173, in client_thread
    requestedFile = open(url, "rb")
FileNotFoundError: [Errno 2] No such file or directory: './a/img_chania.jpg'
Server exception occurred
Traceback (most recent call last):
  File "http.py", line 173, in client_thread
    requestedFile = open(url, "rb")
FileNotFoundError: [Errno 2] No such file or directory: './a/1920px-HTTP_logo.svg.png'
Server exception occurred
Traceback (most recent call last):
  File "http.py", line 173, in client_thread
    requestedFile = open(url, "rb")
FileNotFoundError: [Errno 2] No such file or directory: './a/traceroute.png'
Server exception occurred
Traceback (most recent call last):
  File "http.py", line 146, in client_thread
    requestBody = parse_body(requestData)
  File "http.py", line 85, in parse_body
    _, body = data.split("\r\n\r\n")
ValueError: not enough values to unpack (expected 2, got 1)
Server exception occurred
Traceback (most recent call last):
  File "http.py", line 146, in client_thread
    requestBody = parse_body(requestData)
  File "http.py", line 85, in parse_body
    _, body = data.split("\r\n\r\n")
ValueError: not enough values to unpack (expected 2, got 1)
Server exception occurred
Traceback (most recent call last):
  File "http.py", line 146, in client_thread
    requestBody = parse_body(requestData)
  File "http.py", line 85, in parse_body
    _, body = data.split("\r\n\r\n")
ValueError: not enough values to unpack (expected 2, got 1)
